2025-02-16 23:11:28,790 - WARNING - [main.py:150] - Failed to verify proxy: http://arrowospff4oxrepy1q-session-mkm7isx4-duration-1800:n5bydwiqk4jjwffx@isp.proxies.fo:10808 - Error: ('Connection aborted.', RemoteDisconnected('Remote end closed connection without response'))
2025-02-16 23:11:30,792 - WARNING - [main.py:156] - No working proxies found!
2025-02-16 23:11:30,835 - INFO - [main.py:594] - Starting KiteAI automation...
2025-02-16 23:11:30,835 - INFO - [main.py:380] - Fetching transactions securely...
2025-02-16 23:11:37,793 - INFO - [main.py:536] - Selected AI Assistant: Kite AI Assistant
2025-02-16 23:11:37,795 - INFO - [main.py:537] - Question: What are the main features of Kite AI?
2025-02-16 23:12:10,694 - INFO - [main.py:418] - Sending secure query to https://deployment-hp4y88pxnqxwlmpxllicjzzn.stag-vxzy.zettablock.com/main
2025-02-16 23:12:32,493 - INFO - [main.py:482] - Reporting usage securely...
2025-02-16 23:14:02,497 - WARNING - [connectionpool.py:870] - Retrying (Retry(total=9, connect=None, read=None, redirect=None, status=None)) after connection broken by 'ReadTimeoutError("HTTPSConnectionPool(host='quests-usage-dev.prod.zettablock.com', port=443): Read timed out. (read timeout=90)")': /api/report_usage
2025-02-16 23:15:43,284 - WARNING - [connectionpool.py:870] - Retrying (Retry(total=8, connect=None, read=None, redirect=None, status=None)) after connection broken by 'ReadTimeoutError("HTTPSConnectionPool(host='quests-usage-dev.prod.zettablock.com', port=443): Read timed out. (read timeout=90)")': /api/report_usage
2025-02-16 23:17:34,083 - WARNING - [connectionpool.py:870] - Retrying (Retry(total=7, connect=None, read=None, redirect=None, status=None)) after connection broken by 'ReadTimeoutError("HTTPSConnectionPool(host='quests-usage-dev.prod.zettablock.com', port=443): Read timed out. (read timeout=90)")': /api/report_usage
2025-02-16 23:19:47,252 - WARNING - [connectionpool.py:870] - Retrying (Retry(total=6, connect=None, read=None, redirect=None, status=None)) after connection broken by 'ReadTimeoutError("HTTPSConnectionPool(host='quests-usage-dev.prod.zettablock.com', port=443): Read timed out. (read timeout=90)")': /api/report_usage
2025-02-16 23:22:38,013 - WARNING - [connectionpool.py:870] - Retrying (Retry(total=5, connect=None, read=None, redirect=None, status=None)) after connection broken by 'ReadTimeoutError("HTTPSConnectionPool(host='quests-usage-dev.prod.zettablock.com', port=443): Read timed out. (read timeout=90)")': /api/report_usage
2025-02-16 23:26:08,993 - WARNING - [connectionpool.py:870] - Retrying (Retry(total=4, connect=None, read=None, redirect=None, status=None)) after connection broken by 'ReadTimeoutError("HTTPSConnectionPool(host='quests-usage-dev.prod.zettablock.com', port=443): Read timed out. (read timeout=90)")': /api/report_usage
2025-02-16 23:29:39,758 - WARNING - [connectionpool.py:870] - Retrying (Retry(total=3, connect=None, read=None, redirect=None, status=None)) after connection broken by 'ReadTimeoutError("HTTPSConnectionPool(host='quests-usage-dev.prod.zettablock.com', port=443): Read timed out. (read timeout=90)")': /api/report_usage
2025-02-16 23:33:10,539 - WARNING - [connectionpool.py:870] - Retrying (Retry(total=2, connect=None, read=None, redirect=None, status=None)) after connection broken by 'ReadTimeoutError("HTTPSConnectionPool(host='quests-usage-dev.prod.zettablock.com', port=443): Read timed out. (read timeout=90)")': /api/report_usage
