2025-02-17 00:39:55,412 - WARNING - [connectionpool.py:870] - Retrying (Retry(total=4, connect=None, read=None, redirect=None, status=None)) after connection broken by 'ReadTimeoutError("HTTPSConnectionPool(host='quests-usage-dev.prod.zettablock.com', port=443): Read timed out. (read timeout=10)")': /health
2025-02-17 00:40:08,314 - WARNING - [connectionpool.py:870] - Retrying (Retry(total=3, connect=None, read=None, redirect=None, status=None)) after connection broken by 'ReadTimeoutError("HTTPSConnectionPool(host='quests-usage-dev.prod.zettablock.com', port=443): Read timed out. (read timeout=10)")': /health
2025-02-17 00:40:23,241 - WARNING - [connectionpool.py:870] - Retrying (Retry(total=2, connect=None, read=None, redirect=None, status=None)) after connection broken by 'ReadTimeoutError("HTTPSConnectionPool(host='quests-usage-dev.prod.zettablock.com', port=443): Read timed out. (read timeout=10)")': /health
2025-02-17 00:40:42,170 - WARNING - [connectionpool.py:870] - Retrying (Retry(total=1, connect=None, read=None, redirect=None, status=None)) after connection broken by 'ReadTimeoutError("HTTPSConnectionPool(host='quests-usage-dev.prod.zettablock.com', port=443): Read timed out. (read timeout=10)")': /health
2025-02-17 00:41:11,806 - WARNING - [connectionpool.py:870] - Retrying (Retry(total=0, connect=None, read=None, redirect=None, status=None)) after connection broken by 'ReadTimeoutError("HTTPSConnectionPool(host='quests-usage-dev.prod.zettablock.com', port=443): Read timed out. (read timeout=10)")': /health
2025-02-17 00:41:22,539 - WARNING - [main.py:229] - Attempt 1/3 failed. Waiting 2 seconds before retry. Error: HTTPSConnectionPool(host='quests-usage-dev.prod.zettablock.com', port=443): Max retries exceeded with url: /health (Caused by ReadTimeoutError("HTTPSConnectionPool(host='quests-usage-dev.prod.zettablock.com', port=443): Read timed out. (read timeout=10)"))
2025-02-17 00:41:35,813 - WARNING - [connectionpool.py:870] - Retrying (Retry(total=4, connect=None, read=None, redirect=None, status=None)) after connection broken by 'ReadTimeoutError("HTTPSConnectionPool(host='quests-usage-dev.prod.zettablock.com', port=443): Read timed out. (read timeout=10)")': /health
2025-02-17 00:41:48,708 - WARNING - [connectionpool.py:870] - Retrying (Retry(total=3, connect=None, read=None, redirect=None, status=None)) after connection broken by 'ReadTimeoutError("HTTPSConnectionPool(host='quests-usage-dev.prod.zettablock.com', port=443): Read timed out. (read timeout=10)")': /health
2025-02-17 00:42:03,501 - WARNING - [connectionpool.py:870] - Retrying (Retry(total=2, connect=None, read=None, redirect=None, status=None)) after connection broken by 'ReadTimeoutError("HTTPSConnectionPool(host='quests-usage-dev.prod.zettablock.com', port=443): Read timed out. (read timeout=10)")': /health
2025-02-17 00:42:22,235 - WARNING - [connectionpool.py:870] - Retrying (Retry(total=1, connect=None, read=None, redirect=None, status=None)) after connection broken by 'ReadTimeoutError("HTTPSConnectionPool(host='quests-usage-dev.prod.zettablock.com', port=443): Read timed out. (read timeout=10)")': /health
2025-02-17 00:42:49,131 - WARNING - [connectionpool.py:870] - Retrying (Retry(total=0, connect=None, read=None, redirect=None, status=None)) after connection broken by 'ReadTimeoutError("HTTPSConnectionPool(host='quests-usage-dev.prod.zettablock.com', port=443): Read timed out. (read timeout=10)")': /health
2025-02-17 00:43:00,039 - WARNING - [main.py:229] - Attempt 2/3 failed. Waiting 4 seconds before retry. Error: HTTPSConnectionPool(host='quests-usage-dev.prod.zettablock.com', port=443): Max retries exceeded with url: /health (Caused by ReadTimeoutError("HTTPSConnectionPool(host='quests-usage-dev.prod.zettablock.com', port=443): Read timed out. (read timeout=10)"))
2025-02-17 00:43:15,053 - WARNING - [connectionpool.py:870] - Retrying (Retry(total=4, connect=None, read=None, redirect=None, status=None)) after connection broken by 'ReadTimeoutError("HTTPSConnectionPool(host='quests-usage-dev.prod.zettablock.com', port=443): Read timed out. (read timeout=10)")': /health
2025-02-17 00:43:27,954 - WARNING - [connectionpool.py:870] - Retrying (Retry(total=3, connect=None, read=None, redirect=None, status=None)) after connection broken by 'ReadTimeoutError("HTTPSConnectionPool(host='quests-usage-dev.prod.zettablock.com', port=443): Read timed out. (read timeout=10)")': /health
2025-02-17 00:43:42,729 - WARNING - [connectionpool.py:870] - Retrying (Retry(total=2, connect=None, read=None, redirect=None, status=None)) after connection broken by 'ReadTimeoutError("HTTPSConnectionPool(host='quests-usage-dev.prod.zettablock.com', port=443): Read timed out. (read timeout=10)")': /health
2025-02-17 00:44:01,461 - WARNING - [connectionpool.py:870] - Retrying (Retry(total=1, connect=None, read=None, redirect=None, status=None)) after connection broken by 'ReadTimeoutError("HTTPSConnectionPool(host='quests-usage-dev.prod.zettablock.com', port=443): Read timed out. (read timeout=10)")': /health
2025-02-17 00:44:28,367 - WARNING - [connectionpool.py:870] - Retrying (Retry(total=0, connect=None, read=None, redirect=None, status=None)) after connection broken by 'ReadTimeoutError("HTTPSConnectionPool(host='quests-usage-dev.prod.zettablock.com', port=443): Read timed out. (read timeout=10)")': /health
2025-02-17 00:44:39,147 - WARNING - [main.py:229] - Attempt 3/3 failed. Waiting 8 seconds before retry. Error: HTTPSConnectionPool(host='quests-usage-dev.prod.zettablock.com', port=443): Max retries exceeded with url: /health (Caused by ReadTimeoutError("HTTPSConnectionPool(host='quests-usage-dev.prod.zettablock.com', port=443): Read timed out. (read timeout=10)"))
2025-02-17 00:44:39,147 - ERROR - [main.py:269] - Request error for https://quests-usage-dev.prod.zettablock.com/health
2025-02-17 00:44:39,147 - ERROR - [main.py:270] - Type: ConnectionError
2025-02-17 00:44:39,147 - ERROR - [main.py:271] - Message: HTTPSConnectionPool(host='quests-usage-dev.prod.zettablock.com', port=443): Max retries exceeded with url: /health (Caused by ReadTimeoutError("HTTPSConnectionPool(host='quests-usage-dev.prod.zettablock.com', port=443): Read timed out. (read timeout=10)"))
2025-02-17 00:44:39,148 - WARNING - [main.py:297] - Connection error - check network connectivity
2025-02-17 00:44:39,148 - ERROR - [main.py:122] - Service health check failed: https://quests-usage-dev.prod.zettablock.com/health
