2025-02-17 00:22:18,129 - INFO - [main.py:313] - Fetching transactions securely...
2025-02-17 00:23:37,531 - INFO - [main.py:351] - Sending secure query to https://deployment-hp4y88pxnqxwlmpxllicjzzn.stag-vxzy.zettablock.com/main
2025-02-17 00:23:54,398 - INFO - [main.py:419] - Reporting usage securely...
2025-02-17 00:25:24,673 - WARNING - [connectionpool.py:870] - Retrying (Retry(total=9, connect=None, read=None, redirect=None, status=None)) after connection broken by 'ReadTimeoutError("HTTPSConnectionPool(host='quests-usage-dev.prod.zettablock.com', port=443): Read timed out. (read timeout=90)")': /api/report_usage
