2025-02-16 21:54:43,102 - INFO - [main.py:282] - Verified proxy: http://arrowospff4oxrepy1q-session-mkm7isx4-duration-1800:n5bydwiqk4jjwffx@isp.proxies.fo:10808
2025-02-16 21:54:43,157 - INFO - [main.py:103] - Starting KiteAI automation...
2025-02-16 21:54:43,157 - INFO - [main.py:329] - Fetching transactions securely...
2025-02-16 21:54:50,456 - WARNING - [connectionpool.py:870] - Retrying (Retry(total=4, connect=None, read=None, redirect=None, status=None)) after connection broken by 'RemoteDisconnected('Remote end closed connection without response')': /api/v2/transactions?filter=validated
2025-02-16 21:54:55,347 - WARNING - [connectionpool.py:870] - Retrying (Retry(total=3, connect=None, read=None, redirect=None, status=None)) after connection broken by 'RemoteDisconnected('Remote end closed connection without response')': /api/v2/transactions?filter=validated
2025-02-16 21:55:03,934 - WARNING - [connectionpool.py:870] - Retrying (Retry(total=2, connect=None, read=None, redirect=None, status=None)) after connection broken by 'RemoteDisconnected('Remote end closed connection without response')': /api/v2/transactions?filter=validated
2025-02-16 21:55:20,511 - WARNING - [connectionpool.py:870] - Retrying (Retry(total=1, connect=None, read=None, redirect=None, status=None)) after connection broken by 'RemoteDisconnected('Remote end closed connection without response')': /api/v2/transactions?filter=validated
2025-02-16 21:55:53,925 - WARNING - [connectionpool.py:870] - Retrying (Retry(total=0, connect=None, read=None, redirect=None, status=None)) after connection broken by 'RemoteDisconnected('Remote end closed connection without response')': /api/v2/transactions?filter=validated
2025-02-16 21:55:54,712 - ERROR - [main.py:493] - Request error for https://testnet.kitescan.ai/api/v2/transactions: HTTPSConnectionPool(host='testnet.kitescan.ai', port=443): Max retries exceeded with url: /api/v2/transactions?filter=validated (Caused by ProtocolError('Connection aborted.', RemoteDisconnected('Remote end closed connection without response')))
2025-02-16 21:55:54,714 - WARNING - [main.py:347] - Failed to fetch transactions
2025-02-16 21:55:54,714 - WARNING - [main.py:637] - No transactions available
2025-02-16 21:55:54,714 - INFO - [main.py:148] - Waiting 10.96 seconds before next interaction...
2025-02-16 21:56:05,671 - INFO - [main.py:329] - Fetching transactions securely...
2025-02-16 21:56:19,307 - WARNING - [connectionpool.py:870] - Retrying (Retry(total=4, connect=None, read=None, redirect=None, status=None)) after connection broken by 'RemoteDisconnected('Remote end closed connection without response')': /api/v2/transactions?filter=validated
2025-02-16 21:56:27,049 - INFO - [main.py:651] - Selected AI Assistant: Crypto Price Assistant
2025-02-16 21:56:27,051 - INFO - [main.py:652] - Question: Which coins are trending now?
2025-02-16 21:56:32,663 - WARNING - [connectionpool.py:870] - Retrying (Retry(total=4, connect=None, read=None, redirect=None, status=None)) after connection broken by 'RemoteDisconnected('Remote end closed connection without response')': /api/user/0x6646de28934127ba20ea5444206cfd1c382a7c17/stats
2025-02-16 21:56:41,321 - WARNING - [connectionpool.py:870] - Retrying (Retry(total=3, connect=None, read=None, redirect=None, status=None)) after connection broken by 'RemoteDisconnected('Remote end closed connection without response')': /api/user/0x6646de28934127ba20ea5444206cfd1c382a7c17/stats
2025-02-16 21:56:52,226 - WARNING - [connectionpool.py:870] - Retrying (Retry(total=2, connect=None, read=None, redirect=None, status=None)) after connection broken by 'RemoteDisconnected('Remote end closed connection without response')': /api/user/0x6646de28934127ba20ea5444206cfd1c382a7c17/stats
2025-02-16 21:57:09,551 - WARNING - [connectionpool.py:870] - Retrying (Retry(total=1, connect=None, read=None, redirect=None, status=None)) after connection broken by 'RemoteDisconnected('Remote end closed connection without response')': /api/user/0x6646de28934127ba20ea5444206cfd1c382a7c17/stats
2025-02-16 21:57:42,575 - WARNING - [connectionpool.py:870] - Retrying (Retry(total=0, connect=None, read=None, redirect=None, status=None)) after connection broken by 'RemoteDisconnected('Remote end closed connection without response')': /api/user/0x6646de28934127ba20ea5444206cfd1c382a7c17/stats
2025-02-16 21:57:47,223 - ERROR - [main.py:493] - Request error for https://quests-usage-dev.prod.zettablock.com/api/user/0x6646de28934127ba20ea5444206cfd1c382a7c17/stats: HTTPSConnectionPool(host='quests-usage-dev.prod.zettablock.com', port=443): Max retries exceeded with url: /api/user/0x6646de28934127ba20ea5444206cfd1c382a7c17/stats (Caused by ProtocolError('Connection aborted.', RemoteDisconnected('Remote end closed connection without response')))
2025-02-16 21:57:47,223 - INFO - [main.py:529] - Sending secure query to https://deployment-nc3y3k7zy6gekszmcsordhu7.stag-vxzy.zettablock.com/main
2025-02-16 21:57:49,394 - WARNING - [connectionpool.py:870] - Retrying (Retry(total=4, connect=None, read=None, redirect=None, status=None)) after connection broken by 'RemoteDisconnected('Remote end closed connection without response')': /main
2025-02-16 21:57:54,158 - WARNING - [connectionpool.py:870] - Retrying (Retry(total=3, connect=None, read=None, redirect=None, status=None)) after connection broken by 'RemoteDisconnected('Remote end closed connection without response')': /main
2025-02-16 21:58:08,591 - WARNING - [connectionpool.py:870] - Retrying (Retry(total=2, connect=None, read=None, redirect=None, status=None)) after connection broken by 'RemoteDisconnected('Remote end closed connection without response')': /main
2025-02-16 21:58:25,244 - WARNING - [connectionpool.py:870] - Retrying (Retry(total=1, connect=None, read=None, redirect=None, status=None)) after connection broken by 'RemoteDisconnected('Remote end closed connection without response')': /main
2025-02-16 21:58:58,129 - WARNING - [connectionpool.py:870] - Retrying (Retry(total=0, connect=None, read=None, redirect=None, status=None)) after connection broken by 'RemoteDisconnected('Remote end closed connection without response')': /main
2025-02-16 21:59:04,830 - INFO - [main.py:594] - Reporting usage securely...
2025-02-16 21:59:08,197 - WARNING - [connectionpool.py:870] - Retrying (Retry(total=4, connect=None, read=None, redirect=None, status=None)) after connection broken by 'RemoteDisconnected('Remote end closed connection without response')': /api/report_usage
2025-02-16 21:59:15,747 - WARNING - [connectionpool.py:870] - Retrying (Retry(total=3, connect=None, read=None, redirect=None, status=None)) after connection broken by 'RemoteDisconnected('Remote end closed connection without response')': /api/report_usage
2025-02-16 21:59:26,793 - WARNING - [connectionpool.py:870] - Retrying (Retry(total=2, connect=None, read=None, redirect=None, status=None)) after connection broken by 'RemoteDisconnected('Remote end closed connection without response')': /api/report_usage
2025-02-16 21:59:43,417 - WARNING - [connectionpool.py:870] - Retrying (Retry(total=1, connect=None, read=None, redirect=None, status=None)) after connection broken by 'RemoteDisconnected('Remote end closed connection without response')': /api/report_usage
2025-02-16 22:00:16,048 - WARNING - [connectionpool.py:870] - Retrying (Retry(total=0, connect=None, read=None, redirect=None, status=None)) after connection broken by 'RemoteDisconnected('Remote end closed connection without response')': /api/report_usage
2025-02-16 22:00:17,137 - ERROR - [main.py:493] - Request error for https://quests-usage-dev.prod.zettablock.com/api/report_usage: HTTPSConnectionPool(host='quests-usage-dev.prod.zettablock.com', port=443): Max retries exceeded with url: /api/report_usage (Caused by ProtocolError('Connection aborted.', RemoteDisconnected('Remote end closed connection without response')))
2025-02-16 22:00:23,875 - WARNING - [connectionpool.py:870] - Retrying (Retry(total=4, connect=None, read=None, redirect=None, status=None)) after connection broken by 'RemoteDisconnected('Remote end closed connection without response')': /api/user/0x6646de28934127ba20ea5444206cfd1c382a7c17/stats
2025-02-16 22:00:28,951 - WARNING - [connectionpool.py:870] - Retrying (Retry(total=3, connect=None, read=None, redirect=None, status=None)) after connection broken by 'RemoteDisconnected('Remote end closed connection without response')': /api/user/0x6646de28934127ba20ea5444206cfd1c382a7c17/stats
2025-02-16 22:00:37,701 - WARNING - [connectionpool.py:870] - Retrying (Retry(total=2, connect=None, read=None, redirect=None, status=None)) after connection broken by 'RemoteDisconnected('Remote end closed connection without response')': /api/user/0x6646de28934127ba20ea5444206cfd1c382a7c17/stats
2025-02-16 22:00:54,308 - WARNING - [connectionpool.py:870] - Retrying (Retry(total=1, connect=None, read=None, redirect=None, status=None)) after connection broken by 'RemoteDisconnected('Remote end closed connection without response')': /api/user/0x6646de28934127ba20ea5444206cfd1c382a7c17/stats
2025-02-16 22:01:27,412 - WARNING - [connectionpool.py:870] - Retrying (Retry(total=0, connect=None, read=None, redirect=None, status=None)) after connection broken by 'RemoteDisconnected('Remote end closed connection without response')': /api/user/0x6646de28934127ba20ea5444206cfd1c382a7c17/stats
2025-02-16 22:01:29,634 - ERROR - [main.py:493] - Request error for https://quests-usage-dev.prod.zettablock.com/api/user/0x6646de28934127ba20ea5444206cfd1c382a7c17/stats: HTTPSConnectionPool(host='quests-usage-dev.prod.zettablock.com', port=443): Max retries exceeded with url: /api/user/0x6646de28934127ba20ea5444206cfd1c382a7c17/stats (Caused by ProtocolError('Connection aborted.', RemoteDisconnected('Remote end closed connection without response')))
2025-02-16 22:01:29,634 - WARNING - [main.py:676] - Interaction may not have been recorded
2025-02-16 22:01:29,634 - INFO - [main.py:148] - Waiting 7.38 seconds before next interaction...
2025-02-16 22:01:37,016 - INFO - [main.py:329] - Fetching transactions securely...
2025-02-16 22:01:44,939 - WARNING - [connectionpool.py:870] - Retrying (Retry(total=4, connect=None, read=None, redirect=None, status=None)) after connection broken by 'RemoteDisconnected('Remote end closed connection without response')': /api/v2/transactions?filter=validated
2025-02-16 22:01:51,386 - WARNING - [connectionpool.py:870] - Retrying (Retry(total=3, connect=None, read=None, redirect=None, status=None)) after connection broken by 'RemoteDisconnected('Remote end closed connection without response')': /api/v2/transactions?filter=validated
2025-02-16 22:02:00,363 - WARNING - [connectionpool.py:870] - Retrying (Retry(total=2, connect=None, read=None, redirect=None, status=None)) after connection broken by 'RemoteDisconnected('Remote end closed connection without response')': /api/v2/transactions?filter=validated
2025-02-16 22:02:17,976 - WARNING - [connectionpool.py:870] - Retrying (Retry(total=1, connect=None, read=None, redirect=None, status=None)) after connection broken by 'RemoteDisconnected('Remote end closed connection without response')': /api/v2/transactions?filter=validated
2025-02-16 22:02:50,596 - WARNING - [connectionpool.py:870] - Retrying (Retry(total=0, connect=None, read=None, redirect=None, status=None)) after connection broken by 'RemoteDisconnected('Remote end closed connection without response')': /api/v2/transactions?filter=validated
2025-02-16 22:02:51,232 - ERROR - [main.py:493] - Request error for https://testnet.kitescan.ai/api/v2/transactions: HTTPSConnectionPool(host='testnet.kitescan.ai', port=443): Max retries exceeded with url: /api/v2/transactions?filter=validated (Caused by ProtocolError('Connection aborted.', RemoteDisconnected('Remote end closed connection without response')))
2025-02-16 22:02:51,232 - WARNING - [main.py:347] - Failed to fetch transactions
2025-02-16 22:02:51,232 - WARNING - [main.py:637] - No transactions available
2025-02-16 22:02:51,234 - INFO - [main.py:148] - Waiting 13.73 seconds before next interaction...
2025-02-16 22:03:04,964 - INFO - [main.py:329] - Fetching transactions securely...
2025-02-16 22:03:05,861 - WARNING - [connectionpool.py:870] - Retrying (Retry(total=4, connect=None, read=None, redirect=None, status=None)) after connection broken by 'RemoteDisconnected('Remote end closed connection without response')': /api/v2/transactions?filter=validated
2025-02-16 22:03:09,071 - INFO - [main.py:651] - Selected AI Assistant: Crypto Price Assistant
2025-02-16 22:03:09,073 - INFO - [main.py:652] - Question: Which coins are trending now?
2025-02-16 22:03:09,717 - WARNING - [connectionpool.py:870] - Retrying (Retry(total=4, connect=None, read=None, redirect=None, status=None)) after connection broken by 'RemoteDisconnected('Remote end closed connection without response')': /api/user/0x6646de28934127ba20ea5444206cfd1c382a7c17/stats
2025-02-16 22:03:14,343 - WARNING - [connectionpool.py:870] - Retrying (Retry(total=3, connect=None, read=None, redirect=None, status=None)) after connection broken by 'RemoteDisconnected('Remote end closed connection without response')': /api/user/0x6646de28934127ba20ea5444206cfd1c382a7c17/stats
2025-02-16 22:03:23,546 - WARNING - [connectionpool.py:870] - Retrying (Retry(total=2, connect=None, read=None, redirect=None, status=None)) after connection broken by 'RemoteDisconnected('Remote end closed connection without response')': /api/user/0x6646de28934127ba20ea5444206cfd1c382a7c17/stats
2025-02-16 22:03:46,563 - WARNING - [connectionpool.py:870] - Retrying (Retry(total=1, connect=None, read=None, redirect=None, status=None)) after connection broken by 'RemoteDisconnected('Remote end closed connection without response')': /api/user/0x6646de28934127ba20ea5444206cfd1c382a7c17/stats
2025-02-16 22:04:22,540 - WARNING - [connectionpool.py:870] - Retrying (Retry(total=0, connect=None, read=None, redirect=None, status=None)) after connection broken by 'RemoteDisconnected('Remote end closed connection without response')': /api/user/0x6646de28934127ba20ea5444206cfd1c382a7c17/stats
2025-02-16 22:04:25,894 - ERROR - [main.py:493] - Request error for https://quests-usage-dev.prod.zettablock.com/api/user/0x6646de28934127ba20ea5444206cfd1c382a7c17/stats: HTTPSConnectionPool(host='quests-usage-dev.prod.zettablock.com', port=443): Max retries exceeded with url: /api/user/0x6646de28934127ba20ea5444206cfd1c382a7c17/stats (Caused by ProtocolError('Connection aborted.', RemoteDisconnected('Remote end closed connection without response')))
2025-02-16 22:04:25,895 - INFO - [main.py:529] - Sending secure query to https://deployment-nc3y3k7zy6gekszmcsordhu7.stag-vxzy.zettablock.com/main
2025-02-16 22:04:27,645 - WARNING - [connectionpool.py:870] - Retrying (Retry(total=4, connect=None, read=None, redirect=None, status=None)) after connection broken by 'RemoteDisconnected('Remote end closed connection without response')': /main
2025-02-16 22:04:33,337 - WARNING - [connectionpool.py:870] - Retrying (Retry(total=3, connect=None, read=None, redirect=None, status=None)) after connection broken by 'RemoteDisconnected('Remote end closed connection without response')': /main
2025-02-16 22:04:41,966 - WARNING - [connectionpool.py:870] - Retrying (Retry(total=2, connect=None, read=None, redirect=None, status=None)) after connection broken by 'RemoteDisconnected('Remote end closed connection without response')': /main
2025-02-16 22:05:00,211 - WARNING - [connectionpool.py:870] - Retrying (Retry(total=1, connect=None, read=None, redirect=None, status=None)) after connection broken by 'RemoteDisconnected('Remote end closed connection without response')': /main
2025-02-16 22:05:03,607 - INFO - [main.py:594] - Reporting usage securely...
2025-02-16 22:05:35,546 - WARNING - [connectionpool.py:870] - Retrying (Retry(total=4, connect=None, read=None, redirect=None, status=None)) after connection broken by 'RemoteDisconnected('Remote end closed connection without response')': /api/report_usage
2025-02-16 22:05:40,233 - WARNING - [connectionpool.py:870] - Retrying (Retry(total=3, connect=None, read=None, redirect=None, status=None)) after connection broken by 'RemoteDisconnected('Remote end closed connection without response')': /api/report_usage
2025-02-16 22:05:48,857 - WARNING - [connectionpool.py:870] - Retrying (Retry(total=2, connect=None, read=None, redirect=None, status=None)) after connection broken by 'RemoteDisconnected('Remote end closed connection without response')': /api/report_usage
2025-02-16 22:06:06,609 - WARNING - [connectionpool.py:870] - Retrying (Retry(total=1, connect=None, read=None, redirect=None, status=None)) after connection broken by 'RemoteDisconnected('Remote end closed connection without response')': /api/report_usage
2025-02-16 22:06:41,340 - WARNING - [connectionpool.py:870] - Retrying (Retry(total=0, connect=None, read=None, redirect=None, status=None)) after connection broken by 'RemoteDisconnected('Remote end closed connection without response')': /api/report_usage
2025-02-16 22:06:51,629 - ERROR - [main.py:493] - Request error for https://quests-usage-dev.prod.zettablock.com/api/report_usage: HTTPSConnectionPool(host='quests-usage-dev.prod.zettablock.com', port=443): Max retries exceeded with url: /api/report_usage (Caused by ProtocolError('Connection aborted.', RemoteDisconnected('Remote end closed connection without response')))
2025-02-16 22:06:56,033 - WARNING - [connectionpool.py:870] - Retrying (Retry(total=4, connect=None, read=None, redirect=None, status=None)) after connection broken by 'RemoteDisconnected('Remote end closed connection without response')': /api/user/0x6646de28934127ba20ea5444206cfd1c382a7c17/stats
2025-02-16 22:07:02,635 - WARNING - [connectionpool.py:870] - Retrying (Retry(total=3, connect=None, read=None, redirect=None, status=None)) after connection broken by 'RemoteDisconnected('Remote end closed connection without response')': /api/user/0x6646de28934127ba20ea5444206cfd1c382a7c17/stats
2025-02-16 22:07:12,796 - WARNING - [connectionpool.py:870] - Retrying (Retry(total=2, connect=None, read=None, redirect=None, status=None)) after connection broken by 'RemoteDisconnected('Remote end closed connection without response')': /api/user/0x6646de28934127ba20ea5444206cfd1c382a7c17/stats
2025-02-16 22:07:29,444 - WARNING - [connectionpool.py:870] - Retrying (Retry(total=1, connect=None, read=None, redirect=None, status=None)) after connection broken by 'RemoteDisconnected('Remote end closed connection without response')': /api/user/0x6646de28934127ba20ea5444206cfd1c382a7c17/stats
2025-02-16 22:08:03,757 - WARNING - [connectionpool.py:870] - Retrying (Retry(total=0, connect=None, read=None, redirect=None, status=None)) after connection broken by 'RemoteDisconnected('Remote end closed connection without response')': /api/user/0x6646de28934127ba20ea5444206cfd1c382a7c17/stats
2025-02-16 22:08:06,385 - ERROR - [main.py:493] - Request error for https://quests-usage-dev.prod.zettablock.com/api/user/0x6646de28934127ba20ea5444206cfd1c382a7c17/stats: HTTPSConnectionPool(host='quests-usage-dev.prod.zettablock.com', port=443): Max retries exceeded with url: /api/user/0x6646de28934127ba20ea5444206cfd1c382a7c17/stats (Caused by ProtocolError('Connection aborted.', RemoteDisconnected('Remote end closed connection without response')))
2025-02-16 22:08:06,387 - INFO - [main.py:524] - Implementing backoff for 16 seconds
2025-02-16 22:08:22,388 - WARNING - [main.py:676] - Interaction may not have been recorded
2025-02-16 22:08:22,388 - INFO - [main.py:148] - Waiting 11.32 seconds before next interaction...
2025-02-16 22:08:33,708 - INFO - [main.py:329] - Fetching transactions securely...
2025-02-16 22:08:45,987 - INFO - [main.py:651] - Selected AI Assistant: Kite AI Assistant
2025-02-16 22:08:45,987 - INFO - [main.py:652] - Question: What are the use cases for Kite AI?
2025-02-16 22:08:49,408 - WARNING - [connectionpool.py:870] - Retrying (Retry(total=4, connect=None, read=None, redirect=None, status=None)) after connection broken by 'RemoteDisconnected('Remote end closed connection without response')': /api/user/0x6646de28934127ba20ea5444206cfd1c382a7c17/stats
2025-02-16 22:08:56,953 - WARNING - [connectionpool.py:870] - Retrying (Retry(total=3, connect=None, read=None, redirect=None, status=None)) after connection broken by 'RemoteDisconnected('Remote end closed connection without response')': /api/user/0x6646de28934127ba20ea5444206cfd1c382a7c17/stats
2025-02-16 22:09:13,485 - WARNING - [connectionpool.py:870] - Retrying (Retry(total=2, connect=None, read=None, redirect=None, status=None)) after connection broken by 'RemoteDisconnected('Remote end closed connection without response')': /api/user/0x6646de28934127ba20ea5444206cfd1c382a7c17/stats
2025-02-16 22:09:32,677 - WARNING - [connectionpool.py:870] - Retrying (Retry(total=1, connect=None, read=None, redirect=None, status=None)) after connection broken by 'RemoteDisconnected('Remote end closed connection without response')': /api/user/0x6646de28934127ba20ea5444206cfd1c382a7c17/stats
2025-02-16 22:10:05,776 - WARNING - [connectionpool.py:870] - Retrying (Retry(total=0, connect=None, read=None, redirect=None, status=None)) after connection broken by 'RemoteDisconnected('Remote end closed connection without response')': /api/user/0x6646de28934127ba20ea5444206cfd1c382a7c17/stats
2025-02-16 22:10:06,626 - ERROR - [main.py:493] - Request error for https://quests-usage-dev.prod.zettablock.com/api/user/0x6646de28934127ba20ea5444206cfd1c382a7c17/stats: HTTPSConnectionPool(host='quests-usage-dev.prod.zettablock.com', port=443): Max retries exceeded with url: /api/user/0x6646de28934127ba20ea5444206cfd1c382a7c17/stats (Caused by ProtocolError('Connection aborted.', RemoteDisconnected('Remote end closed connection without response')))
2025-02-16 22:10:06,626 - INFO - [main.py:524] - Implementing backoff for 32 seconds
2025-02-16 22:10:38,627 - INFO - [main.py:529] - Sending secure query to https://deployment-hp4y88pxnqxwlmpxllicjzzn.stag-vxzy.zettablock.com/main
2025-02-16 22:10:47,013 - WARNING - [connectionpool.py:870] - Retrying (Retry(total=4, connect=None, read=None, redirect=None, status=None)) after connection broken by 'RemoteDisconnected('Remote end closed connection without response')': /main
2025-02-16 22:10:57,324 - WARNING - [connectionpool.py:870] - Retrying (Retry(total=3, connect=None, read=None, redirect=None, status=None)) after connection broken by 'RemoteDisconnected('Remote end closed connection without response')': /main
2025-02-16 22:11:10,559 - WARNING - [connectionpool.py:870] - Retrying (Retry(total=2, connect=None, read=None, redirect=None, status=None)) after connection broken by 'RemoteDisconnected('Remote end closed connection without response')': /main
2025-02-16 22:11:33,288 - WARNING - [connectionpool.py:870] - Retrying (Retry(total=1, connect=None, read=None, redirect=None, status=None)) after connection broken by 'RemoteDisconnected('Remote end closed connection without response')': /main
2025-02-16 22:12:17,548 - WARNING - [connectionpool.py:870] - Retrying (Retry(total=0, connect=None, read=None, redirect=None, status=None)) after connection broken by 'RemoteDisconnected('Remote end closed connection without response')': /main
2025-02-16 22:12:19,017 - ERROR - [main.py:493] - Request error for https://deployment-hp4y88pxnqxwlmpxllicjzzn.stag-vxzy.zettablock.com/main: HTTPSConnectionPool(host='deployment-hp4y88pxnqxwlmpxllicjzzn.stag-vxzy.zettablock.com', port=443): Max retries exceeded with url: /main (Caused by ProtocolError('Connection aborted.', RemoteDisconnected('Remote end closed connection without response')))
2025-02-16 22:12:19,017 - INFO - [main.py:148] - Waiting 14.82 seconds before next interaction...
2025-02-16 22:12:33,838 - INFO - [main.py:329] - Fetching transactions securely...
2025-02-16 22:12:38,001 - WARNING - [connectionpool.py:870] - Retrying (Retry(total=4, connect=None, read=None, redirect=None, status=None)) after connection broken by 'RemoteDisconnected('Remote end closed connection without response')': /api/v2/transactions?filter=validated
2025-02-16 22:12:44,621 - WARNING - [connectionpool.py:870] - Retrying (Retry(total=3, connect=None, read=None, redirect=None, status=None)) after connection broken by 'RemoteDisconnected('Remote end closed connection without response')': /api/v2/transactions?filter=validated
2025-02-16 22:12:56,706 - WARNING - [connectionpool.py:870] - Retrying (Retry(total=2, connect=None, read=None, redirect=None, status=None)) after connection broken by 'RemoteDisconnected('Remote end closed connection without response')': /api/v2/transactions?filter=validated
2025-02-16 22:13:14,513 - WARNING - [connectionpool.py:870] - Retrying (Retry(total=1, connect=None, read=None, redirect=None, status=None)) after connection broken by 'RemoteDisconnected('Remote end closed connection without response')': /api/v2/transactions?filter=validated
2025-02-16 22:13:49,374 - WARNING - [connectionpool.py:870] - Retrying (Retry(total=0, connect=None, read=None, redirect=None, status=None)) after connection broken by 'RemoteDisconnected('Remote end closed connection without response')': /api/v2/transactions?filter=validated
2025-02-16 22:13:54,543 - ERROR - [main.py:493] - Request error for https://testnet.kitescan.ai/api/v2/transactions: HTTPSConnectionPool(host='testnet.kitescan.ai', port=443): Max retries exceeded with url: /api/v2/transactions?filter=validated (Caused by ProtocolError('Connection aborted.', RemoteDisconnected('Remote end closed connection without response')))
2025-02-16 22:13:54,545 - WARNING - [main.py:347] - Failed to fetch transactions
2025-02-16 22:13:54,545 - WARNING - [main.py:637] - No transactions available
2025-02-16 22:13:54,545 - INFO - [main.py:148] - Waiting 7.89 seconds before next interaction...
2025-02-16 22:14:02,438 - INFO - [main.py:329] - Fetching transactions securely...
2025-02-16 22:14:08,526 - WARNING - [connectionpool.py:870] - Retrying (Retry(total=4, connect=None, read=None, redirect=None, status=None)) after connection broken by 'RemoteDisconnected('Remote end closed connection without response')': /api/v2/transactions?filter=validated
2025-02-16 22:14:18,427 - WARNING - [connectionpool.py:870] - Retrying (Retry(total=3, connect=None, read=None, redirect=None, status=None)) after connection broken by 'RemoteDisconnected('Remote end closed connection without response')': /api/v2/transactions?filter=validated
2025-02-16 22:14:30,609 - INFO - [main.py:651] - Selected AI Assistant: Transaction Analyzer
2025-02-16 22:14:30,611 - INFO - [main.py:652] - Question: What do you think of this transaction? 0xeddf5f53ba66def871906ef72797c2cfb8dbdd95da87d567d59b17af08cb69a0
2025-02-16 22:14:41,688 - WARNING - [connectionpool.py:870] - Retrying (Retry(total=4, connect=None, read=None, redirect=None, status=None)) after connection broken by 'RemoteDisconnected('Remote end closed connection without response')': /api/user/0x6646de28934127ba20ea5444206cfd1c382a7c17/stats
2025-02-16 22:14:50,124 - WARNING - [connectionpool.py:870] - Retrying (Retry(total=3, connect=None, read=None, redirect=None, status=None)) after connection broken by 'RemoteDisconnected('Remote end closed connection without response')': /api/user/0x6646de28934127ba20ea5444206cfd1c382a7c17/stats
2025-02-16 22:14:59,048 - WARNING - [connectionpool.py:870] - Retrying (Retry(total=2, connect=None, read=None, redirect=None, status=None)) after connection broken by 'RemoteDisconnected('Remote end closed connection without response')': /api/user/0x6646de28934127ba20ea5444206cfd1c382a7c17/stats
2025-02-16 22:15:17,893 - WARNING - [connectionpool.py:870] - Retrying (Retry(total=1, connect=None, read=None, redirect=None, status=None)) after connection broken by 'RemoteDisconnected('Remote end closed connection without response')': /api/user/0x6646de28934127ba20ea5444206cfd1c382a7c17/stats
2025-02-16 22:15:53,814 - WARNING - [connectionpool.py:870] - Retrying (Retry(total=0, connect=None, read=None, redirect=None, status=None)) after connection broken by 'RemoteDisconnected('Remote end closed connection without response')': /api/user/0x6646de28934127ba20ea5444206cfd1c382a7c17/stats
2025-02-16 22:15:57,616 - ERROR - [main.py:493] - Request error for https://quests-usage-dev.prod.zettablock.com/api/user/0x6646de28934127ba20ea5444206cfd1c382a7c17/stats: HTTPSConnectionPool(host='quests-usage-dev.prod.zettablock.com', port=443): Max retries exceeded with url: /api/user/0x6646de28934127ba20ea5444206cfd1c382a7c17/stats (Caused by ProtocolError('Connection aborted.', RemoteDisconnected('Remote end closed connection without response')))
2025-02-16 22:15:57,616 - INFO - [main.py:524] - Implementing backoff for 64 seconds
2025-02-16 22:17:01,618 - INFO - [main.py:529] - Sending secure query to https://deployment-sofftlsf9z4fya3qchykaanq.stag-vxzy.zettablock.com/main
2025-02-16 22:17:13,309 - WARNING - [connectionpool.py:870] - Retrying (Retry(total=4, connect=None, read=None, redirect=None, status=None)) after connection broken by 'RemoteDisconnected('Remote end closed connection without response')': /main
2025-02-16 22:17:20,540 - WARNING - [connectionpool.py:870] - Retrying (Retry(total=3, connect=None, read=None, redirect=None, status=None)) after connection broken by 'RemoteDisconnected('Remote end closed connection without response')': /main
2025-02-16 22:17:29,266 - WARNING - [connectionpool.py:870] - Retrying (Retry(total=2, connect=None, read=None, redirect=None, status=None)) after connection broken by 'RemoteDisconnected('Remote end closed connection without response')': /main
2025-02-16 22:17:46,613 - WARNING - [connectionpool.py:870] - Retrying (Retry(total=1, connect=None, read=None, redirect=None, status=None)) after connection broken by 'RemoteDisconnected('Remote end closed connection without response')': /main
2025-02-16 22:18:24,435 - WARNING - [connectionpool.py:870] - Retrying (Retry(total=0, connect=None, read=None, redirect=None, status=None)) after connection broken by 'RemoteDisconnected('Remote end closed connection without response')': /main
2025-02-16 22:18:29,587 - ERROR - [main.py:493] - Request error for https://deployment-sofftlsf9z4fya3qchykaanq.stag-vxzy.zettablock.com/main: HTTPSConnectionPool(host='deployment-sofftlsf9z4fya3qchykaanq.stag-vxzy.zettablock.com', port=443): Max retries exceeded with url: /main (Caused by ProtocolError('Connection aborted.', RemoteDisconnected('Remote end closed connection without response')))
2025-02-16 22:18:29,587 - INFO - [main.py:148] - Waiting 7.44 seconds before next interaction...
2025-02-16 22:18:37,028 - INFO - [main.py:329] - Fetching transactions securely...
2025-02-16 22:18:44,471 - WARNING - [connectionpool.py:870] - Retrying (Retry(total=4, connect=None, read=None, redirect=None, status=None)) after connection broken by 'RemoteDisconnected('Remote end closed connection without response')': /api/v2/transactions?filter=validated
2025-02-16 22:18:54,659 - WARNING - [connectionpool.py:870] - Retrying (Retry(total=3, connect=None, read=None, redirect=None, status=None)) after connection broken by 'RemoteDisconnected('Remote end closed connection without response')': /api/v2/transactions?filter=validated
2025-02-16 22:19:09,334 - WARNING - [connectionpool.py:870] - Retrying (Retry(total=2, connect=None, read=None, redirect=None, status=None)) after connection broken by 'RemoteDisconnected('Remote end closed connection without response')': /api/v2/transactions?filter=validated
2025-02-16 22:19:32,844 - WARNING - [connectionpool.py:870] - Retrying (Retry(total=1, connect=None, read=None, redirect=None, status=None)) after connection broken by 'RemoteDisconnected('Remote end closed connection without response')': /api/v2/transactions?filter=validated
2025-02-16 22:20:08,403 - WARNING - [connectionpool.py:870] - Retrying (Retry(total=0, connect=None, read=None, redirect=None, status=None)) after connection broken by 'RemoteDisconnected('Remote end closed connection without response')': /api/v2/transactions?filter=validated
2025-02-16 22:20:10,702 - ERROR - [main.py:493] - Request error for https://testnet.kitescan.ai/api/v2/transactions: HTTPSConnectionPool(host='testnet.kitescan.ai', port=443): Max retries exceeded with url: /api/v2/transactions?filter=validated (Caused by ProtocolError('Connection aborted.', RemoteDisconnected('Remote end closed connection without response')))
2025-02-16 22:20:10,704 - INFO - [main.py:524] - Implementing backoff for 16 seconds
2025-02-16 22:20:26,705 - WARNING - [main.py:347] - Failed to fetch transactions
2025-02-16 22:20:26,705 - WARNING - [main.py:637] - No transactions available
2025-02-16 22:20:26,705 - INFO - [main.py:148] - Waiting 7.49 seconds before next interaction...
2025-02-16 22:20:34,193 - INFO - [main.py:329] - Fetching transactions securely...
2025-02-16 22:20:41,756 - WARNING - [connectionpool.py:870] - Retrying (Retry(total=4, connect=None, read=None, redirect=None, status=None)) after connection broken by 'RemoteDisconnected('Remote end closed connection without response')': /api/v2/transactions?filter=validated
2025-02-16 22:20:50,995 - WARNING - [connectionpool.py:870] - Retrying (Retry(total=3, connect=None, read=None, redirect=None, status=None)) after connection broken by 'RemoteDisconnected('Remote end closed connection without response')': /api/v2/transactions?filter=validated
2025-02-16 22:21:07,806 - WARNING - [connectionpool.py:870] - Retrying (Retry(total=2, connect=None, read=None, redirect=None, status=None)) after connection broken by 'RemoteDisconnected('Remote end closed connection without response')': /api/v2/transactions?filter=validated
2025-02-16 22:21:30,506 - WARNING - [connectionpool.py:870] - Retrying (Retry(total=1, connect=None, read=None, redirect=None, status=None)) after connection broken by 'RemoteDisconnected('Remote end closed connection without response')': /api/v2/transactions?filter=validated
2025-02-16 22:22:10,327 - WARNING - [connectionpool.py:870] - Retrying (Retry(total=0, connect=None, read=None, redirect=None, status=None)) after connection broken by 'RemoteDisconnected('Remote end closed connection without response')': /api/v2/transactions?filter=validated
2025-02-16 22:22:16,960 - INFO - [main.py:651] - Selected AI Assistant: Crypto Price Assistant
2025-02-16 22:22:16,962 - INFO - [main.py:652] - Question: Show me Ethereum price trends
2025-02-16 22:22:48,308 - WARNING - [connectionpool.py:870] - Retrying (Retry(total=4, connect=None, read=None, redirect=None, status=None)) after connection broken by 'RemoteDisconnected('Remote end closed connection without response')': /api/user/0x6646de28934127ba20ea5444206cfd1c382a7c17/stats
2025-02-16 22:23:51,951 - ERROR - [main.py:493] - Request error for https://quests-usage-dev.prod.zettablock.com/api/user/0x6646de28934127ba20ea5444206cfd1c382a7c17/stats: HTTPSConnectionPool(host='quests-usage-dev.prod.zettablock.com', port=443): Max retries exceeded with url: /api/user/0x6646de28934127ba20ea5444206cfd1c382a7c17/stats (Caused by ProtocolError('Connection aborted.', RemoteDisconnected('Remote end closed connection without response')))
2025-02-16 22:23:51,951 - INFO - [main.py:524] - Implementing backoff for 128 seconds
2025-02-16 22:25:59,953 - INFO - [main.py:529] - Sending secure query to https://deployment-nc3y3k7zy6gekszmcsordhu7.stag-vxzy.zettablock.com/main
2025-02-16 22:26:04,515 - WARNING - [connectionpool.py:870] - Retrying (Retry(total=4, connect=None, read=None, redirect=None, status=None)) after connection broken by 'RemoteDisconnected('Remote end closed connection without response')': /main
2025-02-16 22:26:13,146 - WARNING - [connectionpool.py:870] - Retrying (Retry(total=3, connect=None, read=None, redirect=None, status=None)) after connection broken by 'RemoteDisconnected('Remote end closed connection without response')': /main
2025-02-16 22:26:26,161 - WARNING - [connectionpool.py:870] - Retrying (Retry(total=2, connect=None, read=None, redirect=None, status=None)) after connection broken by 'RemoteDisconnected('Remote end closed connection without response')': /main
2025-02-16 22:26:46,356 - WARNING - [connectionpool.py:870] - Retrying (Retry(total=1, connect=None, read=None, redirect=None, status=None)) after connection broken by 'RemoteDisconnected('Remote end closed connection without response')': /main
2025-02-16 22:27:19,525 - WARNING - [connectionpool.py:870] - Retrying (Retry(total=0, connect=None, read=None, redirect=None, status=None)) after connection broken by 'RemoteDisconnected('Remote end closed connection without response')': /main
2025-02-16 22:27:26,249 - INFO - [main.py:594] - Reporting usage securely...
2025-02-16 22:28:01,806 - WARNING - [connectionpool.py:870] - Retrying (Retry(total=4, connect=None, read=None, redirect=None, status=None)) after connection broken by 'RemoteDisconnected('Remote end closed connection without response')': /api/report_usage
2025-02-16 22:28:06,925 - WARNING - [connectionpool.py:870] - Retrying (Retry(total=3, connect=None, read=None, redirect=None, status=None)) after connection broken by 'RemoteDisconnected('Remote end closed connection without response')': /api/report_usage
2025-02-16 22:28:46,604 - WARNING - [connectionpool.py:870] - Retrying (Retry(total=2, connect=None, read=None, redirect=None, status=None)) after connection broken by 'RemoteDisconnected('Remote end closed connection without response')': /api/report_usage
2025-02-16 22:29:04,646 - WARNING - [connectionpool.py:870] - Retrying (Retry(total=1, connect=None, read=None, redirect=None, status=None)) after connection broken by 'RemoteDisconnected('Remote end closed connection without response')': /api/report_usage
2025-02-16 22:29:37,388 - WARNING - [connectionpool.py:870] - Retrying (Retry(total=0, connect=None, read=None, redirect=None, status=None)) after connection broken by 'RemoteDisconnected('Remote end closed connection without response')': /api/report_usage
2025-02-16 22:29:37,963 - ERROR - [main.py:493] - Request error for https://quests-usage-dev.prod.zettablock.com/api/report_usage: HTTPSConnectionPool(host='quests-usage-dev.prod.zettablock.com', port=443): Max retries exceeded with url: /api/report_usage (Caused by ProtocolError('Connection aborted.', RemoteDisconnected('Remote end closed connection without response')))
2025-02-16 22:30:09,524 - WARNING - [connectionpool.py:870] - Retrying (Retry(total=4, connect=None, read=None, redirect=None, status=None)) after connection broken by 'RemoteDisconnected('Remote end closed connection without response')': /api/user/0x6646de28934127ba20ea5444206cfd1c382a7c17/stats
2025-02-16 22:30:44,890 - WARNING - [connectionpool.py:870] - Retrying (Retry(total=3, connect=None, read=None, redirect=None, status=None)) after connection broken by 'RemoteDisconnected('Remote end closed connection without response')': /api/user/0x6646de28934127ba20ea5444206cfd1c382a7c17/stats
2025-02-16 22:31:24,451 - WARNING - [connectionpool.py:870] - Retrying (Retry(total=2, connect=None, read=None, redirect=None, status=None)) after connection broken by 'RemoteDisconnected('Remote end closed connection without response')': /api/user/0x6646de28934127ba20ea5444206cfd1c382a7c17/stats
2025-02-16 22:31:41,197 - WARNING - [connectionpool.py:870] - Retrying (Retry(total=1, connect=None, read=None, redirect=None, status=None)) after connection broken by 'RemoteDisconnected('Remote end closed connection without response')': /api/user/0x6646de28934127ba20ea5444206cfd1c382a7c17/stats
2025-02-16 22:32:14,140 - WARNING - [connectionpool.py:870] - Retrying (Retry(total=0, connect=None, read=None, redirect=None, status=None)) after connection broken by 'RemoteDisconnected('Remote end closed connection without response')': /api/user/0x6646de28934127ba20ea5444206cfd1c382a7c17/stats
2025-02-16 22:32:15,463 - ERROR - [main.py:493] - Request error for https://quests-usage-dev.prod.zettablock.com/api/user/0x6646de28934127ba20ea5444206cfd1c382a7c17/stats: HTTPSConnectionPool(host='quests-usage-dev.prod.zettablock.com', port=443): Max retries exceeded with url: /api/user/0x6646de28934127ba20ea5444206cfd1c382a7c17/stats (Caused by ProtocolError('Connection aborted.', RemoteDisconnected('Remote end closed connection without response')))
2025-02-16 22:32:15,463 - INFO - [main.py:524] - Implementing backoff for 256 seconds
2025-02-16 22:36:31,466 - WARNING - [main.py:676] - Interaction may not have been recorded
2025-02-16 22:36:31,466 - INFO - [main.py:148] - Waiting 5.24 seconds before next interaction...
2025-02-16 22:36:36,710 - INFO - [main.py:329] - Fetching transactions securely...
2025-02-16 22:36:40,774 - WARNING - [connectionpool.py:870] - Retrying (Retry(total=4, connect=None, read=None, redirect=None, status=None)) after connection broken by 'RemoteDisconnected('Remote end closed connection without response')': /api/v2/transactions?filter=validated
2025-02-16 22:36:46,030 - WARNING - [connectionpool.py:870] - Retrying (Retry(total=3, connect=None, read=None, redirect=None, status=None)) after connection broken by 'RemoteDisconnected('Remote end closed connection without response')': /api/v2/transactions?filter=validated
2025-02-16 22:36:55,049 - WARNING - [connectionpool.py:870] - Retrying (Retry(total=2, connect=None, read=None, redirect=None, status=None)) after connection broken by 'RemoteDisconnected('Remote end closed connection without response')': /api/v2/transactions?filter=validated
2025-02-16 22:37:11,854 - WARNING - [connectionpool.py:870] - Retrying (Retry(total=1, connect=None, read=None, redirect=None, status=None)) after connection broken by 'RemoteDisconnected('Remote end closed connection without response')': /api/v2/transactions?filter=validated
2025-02-16 22:37:44,559 - WARNING - [connectionpool.py:870] - Retrying (Retry(total=0, connect=None, read=None, redirect=None, status=None)) after connection broken by 'RemoteDisconnected('Remote end closed connection without response')': /api/v2/transactions?filter=validated
2025-02-16 22:37:45,182 - ERROR - [main.py:493] - Request error for https://testnet.kitescan.ai/api/v2/transactions: HTTPSConnectionPool(host='testnet.kitescan.ai', port=443): Max retries exceeded with url: /api/v2/transactions?filter=validated (Caused by ProtocolError('Connection aborted.', RemoteDisconnected('Remote end closed connection without response')))
2025-02-16 22:37:45,182 - INFO - [main.py:524] - Implementing backoff for 32 seconds
2025-02-16 22:38:17,184 - WARNING - [main.py:347] - Failed to fetch transactions
2025-02-16 22:38:17,184 - WARNING - [main.py:637] - No transactions available
2025-02-16 22:38:17,184 - INFO - [main.py:148] - Waiting 5.66 seconds before next interaction...
2025-02-16 22:38:22,843 - INFO - [main.py:329] - Fetching transactions securely...
2025-02-16 22:38:23,474 - WARNING - [connectionpool.py:870] - Retrying (Retry(total=4, connect=None, read=None, redirect=None, status=None)) after connection broken by 'RemoteDisconnected('Remote end closed connection without response')': /api/v2/transactions?filter=validated
2025-02-16 22:38:28,085 - WARNING - [connectionpool.py:870] - Retrying (Retry(total=3, connect=None, read=None, redirect=None, status=None)) after connection broken by 'RemoteDisconnected('Remote end closed connection without response')': /api/v2/transactions?filter=validated
2025-02-16 22:38:36,839 - WARNING - [connectionpool.py:870] - Retrying (Retry(total=2, connect=None, read=None, redirect=None, status=None)) after connection broken by 'RemoteDisconnected('Remote end closed connection without response')': /api/v2/transactions?filter=validated
2025-02-16 22:38:53,568 - WARNING - [connectionpool.py:870] - Retrying (Retry(total=1, connect=None, read=None, redirect=None, status=None)) after connection broken by 'RemoteDisconnected('Remote end closed connection without response')': /api/v2/transactions?filter=validated
2025-02-16 22:39:26,136 - WARNING - [connectionpool.py:870] - Retrying (Retry(total=0, connect=None, read=None, redirect=None, status=None)) after connection broken by 'RemoteDisconnected('Remote end closed connection without response')': /api/v2/transactions?filter=validated
2025-02-16 22:39:26,697 - ERROR - [main.py:493] - Request error for https://testnet.kitescan.ai/api/v2/transactions: HTTPSConnectionPool(host='testnet.kitescan.ai', port=443): Max retries exceeded with url: /api/v2/transactions?filter=validated (Caused by ProtocolError('Connection aborted.', RemoteDisconnected('Remote end closed connection without response')))
2025-02-16 22:39:26,697 - INFO - [main.py:524] - Implementing backoff for 64 seconds
2025-02-16 22:40:30,699 - WARNING - [main.py:347] - Failed to fetch transactions
2025-02-16 22:40:30,699 - WARNING - [main.py:637] - No transactions available
2025-02-16 22:40:30,699 - INFO - [main.py:148] - Waiting 7.59 seconds before next interaction...
2025-02-16 22:40:38,290 - INFO - [main.py:329] - Fetching transactions securely...
2025-02-16 22:40:39,015 - WARNING - [connectionpool.py:870] - Retrying (Retry(total=4, connect=None, read=None, redirect=None, status=None)) after connection broken by 'RemoteDisconnected('Remote end closed connection without response')': /api/v2/transactions?filter=validated
2025-02-16 22:40:43,721 - WARNING - [connectionpool.py:870] - Retrying (Retry(total=3, connect=None, read=None, redirect=None, status=None)) after connection broken by 'RemoteDisconnected('Remote end closed connection without response')': /api/v2/transactions?filter=validated
2025-02-16 22:40:52,397 - WARNING - [connectionpool.py:870] - Retrying (Retry(total=2, connect=None, read=None, redirect=None, status=None)) after connection broken by 'RemoteDisconnected('Remote end closed connection without response')': /api/v2/transactions?filter=validated
2025-02-16 22:41:09,139 - WARNING - [connectionpool.py:870] - Retrying (Retry(total=1, connect=None, read=None, redirect=None, status=None)) after connection broken by 'RemoteDisconnected('Remote end closed connection without response')': /api/v2/transactions?filter=validated
2025-02-16 22:41:41,935 - WARNING - [connectionpool.py:870] - Retrying (Retry(total=0, connect=None, read=None, redirect=None, status=None)) after connection broken by 'RemoteDisconnected('Remote end closed connection without response')': /api/v2/transactions?filter=validated
2025-02-16 22:41:57,033 - INFO - [main.py:651] - Selected AI Assistant: Transaction Analyzer
2025-02-16 22:41:57,035 - INFO - [main.py:652] - Question: What do you think of this transaction? 0x4a20275b96e26cb078117641d913f9513a0e004872542f10953a1c9aee5bf9cf
2025-02-16 22:42:28,539 - WARNING - [connectionpool.py:870] - Retrying (Retry(total=4, connect=None, read=None, redirect=None, status=None)) after connection broken by 'RemoteDisconnected('Remote end closed connection without response')': /api/user/0x6646de28934127ba20ea5444206cfd1c382a7c17/stats
2025-02-16 22:43:03,908 - WARNING - [connectionpool.py:870] - Retrying (Retry(total=3, connect=None, read=None, redirect=None, status=None)) after connection broken by 'RemoteDisconnected('Remote end closed connection without response')': /api/user/0x6646de28934127ba20ea5444206cfd1c382a7c17/stats
2025-02-16 22:43:43,445 - WARNING - [connectionpool.py:870] - Retrying (Retry(total=2, connect=None, read=None, redirect=None, status=None)) after connection broken by 'RemoteDisconnected('Remote end closed connection without response')': /api/user/0x6646de28934127ba20ea5444206cfd1c382a7c17/stats
2025-02-16 22:44:36,716 - ERROR - [main.py:493] - Request error for https://quests-usage-dev.prod.zettablock.com/api/user/0x6646de28934127ba20ea5444206cfd1c382a7c17/stats: HTTPSConnectionPool(host='quests-usage-dev.prod.zettablock.com', port=443): Max retries exceeded with url: /api/user/0x6646de28934127ba20ea5444206cfd1c382a7c17/stats (Caused by ProtocolError('Connection aborted.', RemoteDisconnected('Remote end closed connection without response')))
2025-02-16 22:44:36,717 - INFO - [main.py:524] - Implementing backoff for 300 seconds
2025-02-16 22:49:36,718 - INFO - [main.py:529] - Sending secure query to https://deployment-sofftlsf9z4fya3qchykaanq.stag-vxzy.zettablock.com/main
2025-02-16 22:49:40,783 - WARNING - [connectionpool.py:870] - Retrying (Retry(total=4, connect=None, read=None, redirect=None, status=None)) after connection broken by 'RemoteDisconnected('Remote end closed connection without response')': /main
2025-02-16 22:49:45,366 - WARNING - [connectionpool.py:870] - Retrying (Retry(total=3, connect=None, read=None, redirect=None, status=None)) after connection broken by 'RemoteDisconnected('Remote end closed connection without response')': /main
2025-02-16 22:49:56,117 - WARNING - [connectionpool.py:870] - Retrying (Retry(total=2, connect=None, read=None, redirect=None, status=None)) after connection broken by 'RemoteDisconnected('Remote end closed connection without response')': /main
2025-02-16 22:50:12,752 - WARNING - [connectionpool.py:870] - Retrying (Retry(total=1, connect=None, read=None, redirect=None, status=None)) after connection broken by 'RemoteDisconnected('Remote end closed connection without response')': /main
2025-02-16 22:50:45,374 - WARNING - [connectionpool.py:870] - Retrying (Retry(total=0, connect=None, read=None, redirect=None, status=None)) after connection broken by 'RemoteDisconnected('Remote end closed connection without response')': /main
2025-02-16 22:50:45,985 - ERROR - [main.py:493] - Request error for https://deployment-sofftlsf9z4fya3qchykaanq.stag-vxzy.zettablock.com/main: HTTPSConnectionPool(host='deployment-sofftlsf9z4fya3qchykaanq.stag-vxzy.zettablock.com', port=443): Max retries exceeded with url: /main (Caused by ProtocolError('Connection aborted.', RemoteDisconnected('Remote end closed connection without response')))
2025-02-16 22:50:45,985 - INFO - [main.py:148] - Waiting 9.61 seconds before next interaction...
2025-02-16 22:50:55,593 - INFO - [main.py:329] - Fetching transactions securely...
2025-02-16 22:51:02,747 - WARNING - [connectionpool.py:870] - Retrying (Retry(total=4, connect=None, read=None, redirect=None, status=None)) after connection broken by 'RemoteDisconnected('Remote end closed connection without response')': /api/v2/transactions?filter=validated
2025-02-16 22:51:07,637 - WARNING - [connectionpool.py:870] - Retrying (Retry(total=3, connect=None, read=None, redirect=None, status=None)) after connection broken by 'RemoteDisconnected('Remote end closed connection without response')': /api/v2/transactions?filter=validated
2025-02-16 22:51:17,424 - WARNING - [connectionpool.py:870] - Retrying (Retry(total=2, connect=None, read=None, redirect=None, status=None)) after connection broken by 'RemoteDisconnected('Remote end closed connection without response')': /api/v2/transactions?filter=validated
2025-02-16 22:51:35,230 - WARNING - [connectionpool.py:870] - Retrying (Retry(total=1, connect=None, read=None, redirect=None, status=None)) after connection broken by 'RemoteDisconnected('Remote end closed connection without response')': /api/v2/transactions?filter=validated
2025-02-16 22:52:08,255 - WARNING - [connectionpool.py:870] - Retrying (Retry(total=0, connect=None, read=None, redirect=None, status=None)) after connection broken by 'RemoteDisconnected('Remote end closed connection without response')': /api/v2/transactions?filter=validated
2025-02-16 22:52:09,547 - ERROR - [main.py:493] - Request error for https://testnet.kitescan.ai/api/v2/transactions: HTTPSConnectionPool(host='testnet.kitescan.ai', port=443): Max retries exceeded with url: /api/v2/transactions?filter=validated (Caused by ProtocolError('Connection aborted.', RemoteDisconnected('Remote end closed connection without response')))
2025-02-16 22:52:09,547 - INFO - [main.py:524] - Implementing backoff for 128 seconds
2025-02-16 22:54:17,550 - WARNING - [main.py:347] - Failed to fetch transactions
2025-02-16 22:54:17,550 - WARNING - [main.py:637] - No transactions available
2025-02-16 22:54:17,550 - INFO - [main.py:148] - Waiting 5.71 seconds before next interaction...
2025-02-16 22:54:23,263 - INFO - [main.py:329] - Fetching transactions securely...
2025-02-16 22:54:24,224 - WARNING - [connectionpool.py:870] - Retrying (Retry(total=4, connect=None, read=None, redirect=None, status=None)) after connection broken by 'RemoteDisconnected('Remote end closed connection without response')': /api/v2/transactions?filter=validated
2025-02-16 22:54:29,012 - WARNING - [connectionpool.py:870] - Retrying (Retry(total=3, connect=None, read=None, redirect=None, status=None)) after connection broken by 'RemoteDisconnected('Remote end closed connection without response')': /api/v2/transactions?filter=validated
2025-02-16 22:54:37,686 - WARNING - [connectionpool.py:870] - Retrying (Retry(total=2, connect=None, read=None, redirect=None, status=None)) after connection broken by 'RemoteDisconnected('Remote end closed connection without response')': /api/v2/transactions?filter=validated
2025-02-16 22:54:56,577 - WARNING - [connectionpool.py:870] - Retrying (Retry(total=1, connect=None, read=None, redirect=None, status=None)) after connection broken by 'RemoteDisconnected('Remote end closed connection without response')': /api/v2/transactions?filter=validated
2025-02-16 22:55:29,187 - WARNING - [connectionpool.py:870] - Retrying (Retry(total=0, connect=None, read=None, redirect=None, status=None)) after connection broken by 'RemoteDisconnected('Remote end closed connection without response')': /api/v2/transactions?filter=validated
2025-02-16 22:55:30,033 - ERROR - [main.py:493] - Request error for https://testnet.kitescan.ai/api/v2/transactions: HTTPSConnectionPool(host='testnet.kitescan.ai', port=443): Max retries exceeded with url: /api/v2/transactions?filter=validated (Caused by ProtocolError('Connection aborted.', RemoteDisconnected('Remote end closed connection without response')))
2025-02-16 22:55:30,033 - INFO - [main.py:524] - Implementing backoff for 256 seconds
2025-02-16 22:59:46,034 - WARNING - [main.py:347] - Failed to fetch transactions
2025-02-16 22:59:46,034 - WARNING - [main.py:637] - No transactions available
2025-02-16 22:59:46,034 - INFO - [main.py:148] - Waiting 13.71 seconds before next interaction...
2025-02-16 22:59:59,745 - INFO - [main.py:329] - Fetching transactions securely...
2025-02-16 23:00:13,019 - INFO - [main.py:651] - Selected AI Assistant: Crypto Price Assistant
2025-02-16 23:00:13,019 - INFO - [main.py:652] - Question: What's the market cap of BNB?
