2025-02-17 00:49:15,059 - INFO - [main.py:225] - Request to https://testnet.kitescan.ai/api/health succeeded with status 200
2025-02-17 00:49:31,025 - WARNING - [connectionpool.py:870] - Retrying (Retry(total=4, connect=None, read=None, redirect=None, status=None)) after connection broken by 'ReadTimeoutError("HTTPSConnectionPool(host='quests-usage-dev.prod.zettablock.com', port=443): Read timed out. (read timeout=15)")': /health
2025-02-17 00:49:48,931 - WARNING - [connectionpool.py:870] - Retrying (Retry(total=3, connect=None, read=None, redirect=None, status=None)) after connection broken by 'ReadTimeoutError("HTTPSConnectionPool(host='quests-usage-dev.prod.zettablock.com', port=443): Read timed out. (read timeout=15)")': /health
2025-02-17 00:50:08,675 - WARNING - [connectionpool.py:870] - Retrying (Retry(total=2, connect=None, read=None, redirect=None, status=None)) after connection broken by 'ReadTimeoutError("HTTPSConnectionPool(host='quests-usage-dev.prod.zettablock.com', port=443): Read timed out. (read timeout=15)")': /health
2025-02-17 00:50:32,564 - WARNING - [connectionpool.py:870] - Retrying (Retry(total=1, connect=None, read=None, redirect=None, status=None)) after connection broken by 'ReadTimeoutError("HTTPSConnectionPool(host='quests-usage-dev.prod.zettablock.com', port=443): Read timed out. (read timeout=15)")': /health
2025-02-17 00:51:04,486 - WARNING - [connectionpool.py:870] - Retrying (Retry(total=0, connect=None, read=None, redirect=None, status=None)) after connection broken by 'ReadTimeoutError("HTTPSConnectionPool(host='quests-usage-dev.prod.zettablock.com', port=443): Read timed out. (read timeout=15)")': /health
2025-02-17 00:51:20,402 - WARNING - [main.py:235] - Request attempt 1/2 failed: HTTPSConnectionPool(host='quests-usage-dev.prod.zettablock.com', port=443): Max retries exceeded with url: /health (Caused by ReadTimeoutError("HTTPSConnectionPool(host='quests-usage-dev.prod.zettablock.com', port=443): Read timed out. (read timeout=15)"))
2025-02-17 00:51:38,144 - WARNING - [connectionpool.py:870] - Retrying (Retry(total=4, connect=None, read=None, redirect=None, status=None)) after connection broken by 'ReadTimeoutError("HTTPSConnectionPool(host='quests-usage-dev.prod.zettablock.com', port=443): Read timed out. (read timeout=15)")': /health
2025-02-17 00:51:54,069 - INFO - [main.py:693] - Received shutdown signal, cleaning up...
